<?xml version="1.0" ?>
<!-- =================================================================================== -->
<!-- |    This document was autogenerated by xacro from AGV2.urdf.xarco                | -->
<!-- |    EDITING THIS FILE BY HAND IS NOT RECOMMENDED                                 | -->
<!-- =================================================================================== -->
<robot name="macroed">
  <material name="green">
    <color rgba="0 0.5 0.2 1"/>
  </material>
  <material name="black">
    <color rgba="0 0 0 1"/>
  </material>
  <material name="white">
    <color rgba="1 1 1 1"/>
  </material>
  <link name="base_link">
    <visual>
      <geometry>
        <box size="1 0.1 1"/>
      </geometry>
      <origin rpy="1.5707963267948966 0 0" xyz="0 0 0"/>
      <material name="green"/>
    </visual>
    <collision>
      <geometry>
        <box size="1 0.1 1"/>
      </geometry>
      <origin rpy="1.5707963267948966 0 0" xyz="0 0 0"/>
    </collision>
    <inertial>
      <mass value="5"/>
      <inertia ixx="0.012538669546367351" ixy="0.0" ixz="0.0" iyy="0.012538669546367351" iyz="0.0" izz="0.012538669546367351"/>
    </inertial>
  </link>
  <!-- <link name="virtual">
  </link> -->
  <link name="right_front_wheel_base">
    <inertial>
      <mass value="0.001"/>
      <inertia ixx="8.576329331046308e-09" ixy="0.0" ixz="0.0" iyy="8.576329331046308e-09" iyz="0.0" izz="8.576329331046308e-09"/>
    </inertial>
  </link>
  <link name="right_front_wheel">
    <visual>
      <origin rpy="1.5707963267948966 0 0" xyz="0 0 0"/>
      <geometry>
        <cylinder length="0.1" radius="0.1"/>
      </geometry>
      <material name="black"/>
    </visual>
    <collision>
      <origin rpy="1.5707963267948966 0 0" xyz="0 0 0"/>
      <geometry>
        <cylinder length="0.1" radius="0.1"/>
      </geometry>
    </collision>
    <inertial>
      <mass value="1"/>
      <inertia ixx="0.0008576329331046312" ixy="0.0" ixz="0.0" iyy="0.0008576329331046312" iyz="0.0" izz="0.0008576329331046312"/>
    </inertial>
  </link>
  <joint name="right_front_wheel_base_joint" type="continuous">
    <axis rpy="0 0 0" xyz="0 0 1"/>
    <parent link="base_link"/>
    <child link="right_front_wheel_base"/>
    <origin rpy="0 0 0" xyz="0.5 0.5 0"/>
  </joint>
  <joint name="right_front_wheel_joint" type="continuous">
    <axis rpy="0 0 0" xyz="0 1 0"/>
    <parent link="right_front_wheel_base"/>
    <child link="right_front_wheel"/>
    <origin rpy="0 0 0" xyz="0 0 -0.15000000000000002"/>
  </joint>
  <link name="right_back_wheel_base">
    <inertial>
      <mass value="0.001"/>
      <inertia ixx="8.576329331046308e-09" ixy="0.0" ixz="0.0" iyy="8.576329331046308e-09" iyz="0.0" izz="8.576329331046308e-09"/>
    </inertial>
  </link>
  <link name="right_back_wheel">
    <visual>
      <origin rpy="1.5707963267948966 0 0" xyz="0 0 0"/>
      <geometry>
        <cylinder length="0.1" radius="0.1"/>
      </geometry>
      <material name="black"/>
    </visual>
    <collision>
      <origin rpy="1.5707963267948966 0 0" xyz="0 0 0"/>
      <geometry>
        <cylinder length="0.1" radius="0.1"/>
      </geometry>
    </collision>
    <inertial>
      <mass value="1"/>
      <inertia ixx="0.0008576329331046312" ixy="0.0" ixz="0.0" iyy="0.0008576329331046312" iyz="0.0" izz="0.0008576329331046312"/>
    </inertial>
  </link>
  <joint name="right_back_wheel_base_joint" type="continuous">
    <axis rpy="0 0 0" xyz="0 0 1"/>
    <parent link="base_link"/>
    <child link="right_back_wheel_base"/>
    <origin rpy="0 0 0" xyz="-0.5 0.5 0"/>
  </joint>
  <joint name="right_back_wheel_joint" type="continuous">
    <axis rpy="0 0 0" xyz="0 1 0"/>
    <parent link="right_back_wheel_base"/>
    <child link="right_back_wheel"/>
    <origin rpy="0 0 0" xyz="0 0 -0.15000000000000002"/>
  </joint>
  <link name="left_front_wheel_base">
    <inertial>
      <mass value="0.001"/>
      <inertia ixx="8.576329331046308e-09" ixy="0.0" ixz="0.0" iyy="8.576329331046308e-09" iyz="0.0" izz="8.576329331046308e-09"/>
    </inertial>
  </link>
  <link name="left_front_wheel">
    <visual>
      <origin rpy="1.5707963267948966 0 0" xyz="0 0 0"/>
      <geometry>
        <cylinder length="0.1" radius="0.1"/>
      </geometry>
      <material name="black"/>
    </visual>
    <collision>
      <origin rpy="1.5707963267948966 0 0" xyz="0 0 0"/>
      <geometry>
        <cylinder length="0.1" radius="0.1"/>
      </geometry>
    </collision>
    <inertial>
      <mass value="1"/>
      <inertia ixx="0.0008576329331046312" ixy="0.0" ixz="0.0" iyy="0.0008576329331046312" iyz="0.0" izz="0.0008576329331046312"/>
    </inertial>
  </link>
  <joint name="left_front_wheel_base_joint" type="continuous">
    <axis rpy="0 0 0" xyz="0 0 1"/>
    <parent link="base_link"/>
    <child link="left_front_wheel_base"/>
    <origin rpy="0 0 0" xyz="0.5 -0.5 0"/>
  </joint>
  <joint name="left_front_wheel_joint" type="continuous">
    <axis rpy="0 0 0" xyz="0 1 0"/>
    <parent link="left_front_wheel_base"/>
    <child link="left_front_wheel"/>
    <origin rpy="0 0 0" xyz="0 0 -0.15000000000000002"/>
  </joint>
  <link name="left_back_wheel_base">
    <inertial>
      <mass value="0.001"/>
      <inertia ixx="8.576329331046308e-09" ixy="0.0" ixz="0.0" iyy="8.576329331046308e-09" iyz="0.0" izz="8.576329331046308e-09"/>
    </inertial>
  </link>
  <link name="left_back_wheel">
    <visual>
      <origin rpy="1.5707963267948966 0 0" xyz="0 0 0"/>
      <geometry>
        <cylinder length="0.1" radius="0.1"/>
      </geometry>
      <material name="black"/>
    </visual>
    <collision>
      <origin rpy="1.5707963267948966 0 0" xyz="0 0 0"/>
      <geometry>
        <cylinder length="0.1" radius="0.1"/>
      </geometry>
    </collision>
    <inertial>
      <mass value="1"/>
      <inertia ixx="0.0008576329331046312" ixy="0.0" ixz="0.0" iyy="0.0008576329331046312" iyz="0.0" izz="0.0008576329331046312"/>
    </inertial>
  </link>
  <joint name="left_back_wheel_base_joint" type="continuous">
    <axis rpy="0 0 0" xyz="0 0 1"/>
    <parent link="base_link"/>
    <child link="left_back_wheel_base"/>
    <origin rpy="0 0 0" xyz="-0.5 -0.5 0"/>
  </joint>
  <joint name="left_back_wheel_joint" type="continuous">
    <axis rpy="0 0 0" xyz="0 1 0"/>
    <parent link="left_back_wheel_base"/>
    <child link="left_back_wheel"/>
    <origin rpy="0 0 0" xyz="0 0 -0.15000000000000002"/>
  </joint>
</robot>