<?xml version="1.0" ?>
<!-- =================================================================================== -->
<!-- |    This document was autogenerated by xacro from ./AGV2.urdf.xarco              | -->
<!-- |    EDITING THIS FILE BY HAND IS NOT RECOMMENDED                                 | -->
<!-- =================================================================================== -->
<robot name="macroed">
  <material name="green">
    <color rgba="0 0.5 0.2 1"/>
  </material>
  <material name="black">
    <color rgba="0 0 0 1"/>
  </material>
  <material name="white">
    <color rgba="1 1 1 1"/>
  </material>
  <link name="base_link">
    <visual>
      <geometry>
        <box size="1 0.1 1"/>
      </geometry>
      <origin rpy="1.5707963267948966 0 0" xyz="0 0 0"/>
      <material name="green"/>
    </visual>
    <collision>
      <geometry>
        <box size="1 0.1 1"/>
      </geometry>
      <origin rpy="1.5707963267948966 0 0" xyz="0 0 0"/>
    </collision>
    <inertial>
      <mass value="0.5"/>
      <inertia ixx="0.001" ixy="0.001" ixz="0.001" iyy="0.001" iyz="0.001" izz="0.001"/>
    </inertial>
  </link>
  <!-- <link name="virtual">
  </link> -->
  <link name="right_front_wheel_base">
    <inertial>
      <mass value="0.001"/>
      <inertia ixx="0.001" ixy="0.001" ixz="0.001" iyy="0.001" iyz="0.001" izz="0.001"/>
    </inertial>
  </link>
  <link name="right_front_wheel">
    <visual>
      <origin rpy="1.5707963267948966 0 0" xyz="0 0 0"/>
      <geometry>
        <cylinder length="0.1" radius="0.1"/>
      </geometry>
      <material name="black"/>
    </visual>
    <collision>
      <origin rpy="1.5707963267948966 0 0" xyz="0 0 0"/>
      <geometry>
        <cylinder length="0.1" radius="0.1"/>
      </geometry>
    </collision>
    <inertial>
      <mass value="0.3"/>
      <inertia ixx="0.001" ixy="0.001" ixz="0.001" iyy="0.001" iyz="0.001" izz="0.001"/>
    </inertial>
  </link>
  <joint name="right_front_wheel_base_joint" type="continuous">
    <axis rpy="0 0 0" xyz="0 0 1"/>
    <parent link="base_link"/>
    <child link="right_front_wheel_base"/>
    <origin rpy="0 0 0" xyz="0.5 0.5 0"/>
  </joint>
  <joint name="right_front_wheel_joint" type="continuous">
    <axis rpy="0 0 0" xyz="0 1 0"/>
    <parent link="right_front_wheel_base"/>
    <child link="right_front_wheel"/>
    <origin rpy="0 0 0" xyz="0 0 -0.15000000000000002"/>
  </joint>
  <!-- <joint name="${prefix}_${suffix}_wheel_joint_revolute" type="revolute">
      <axis rpy="0 0 0" xyz="0 0 1"/>
      <limit effort ="1000.0" lower="-0.55" upper="0.55" velocity="0.5"/>
      <parent link="${prefix}_${suffix}_wheel"/>
      <child link="${prefix}_${suffix}_wheel"/>
      <origin rpy="0 0 0" xyz="${width*reflectx/2} ${width/2*reflecty} -${wheeldiam/2+.05}"/>
    </joint> -->
  <link name="right_back_wheel_base">
    <inertial>
      <mass value="0.001"/>
      <inertia ixx="0.001" ixy="0.001" ixz="0.001" iyy="0.001" iyz="0.001" izz="0.001"/>
    </inertial>
  </link>
  <link name="right_back_wheel">
    <visual>
      <origin rpy="1.5707963267948966 0 0" xyz="0 0 0"/>
      <geometry>
        <cylinder length="0.1" radius="0.1"/>
      </geometry>
      <material name="black"/>
    </visual>
    <collision>
      <origin rpy="1.5707963267948966 0 0" xyz="0 0 0"/>
      <geometry>
        <cylinder length="0.1" radius="0.1"/>
      </geometry>
    </collision>
    <inertial>
      <mass value="0.3"/>
      <inertia ixx="0.001" ixy="0.001" ixz="0.001" iyy="0.001" iyz="0.001" izz="0.001"/>
    </inertial>
  </link>
  <joint name="right_back_wheel_base_joint" type="continuous">
    <axis rpy="0 0 0" xyz="0 0 1"/>
    <parent link="base_link"/>
    <child link="right_back_wheel_base"/>
    <origin rpy="0 0 0" xyz="-0.5 0.5 0"/>
  </joint>
  <joint name="right_back_wheel_joint" type="continuous">
    <axis rpy="0 0 0" xyz="0 1 0"/>
    <parent link="right_back_wheel_base"/>
    <child link="right_back_wheel"/>
    <origin rpy="0 0 0" xyz="0 0 -0.15000000000000002"/>
  </joint>
  <!-- <joint name="${prefix}_${suffix}_wheel_joint_revolute" type="revolute">
      <axis rpy="0 0 0" xyz="0 0 1"/>
      <limit effort ="1000.0" lower="-0.55" upper="0.55" velocity="0.5"/>
      <parent link="${prefix}_${suffix}_wheel"/>
      <child link="${prefix}_${suffix}_wheel"/>
      <origin rpy="0 0 0" xyz="${width*reflectx/2} ${width/2*reflecty} -${wheeldiam/2+.05}"/>
    </joint> -->
  <link name="left_front_wheel_base">
    <inertial>
      <mass value="0.001"/>
      <inertia ixx="0.001" ixy="0.001" ixz="0.001" iyy="0.001" iyz="0.001" izz="0.001"/>
    </inertial>
  </link>
  <link name="left_front_wheel">
    <visual>
      <origin rpy="1.5707963267948966 0 0" xyz="0 0 0"/>
      <geometry>
        <cylinder length="0.1" radius="0.1"/>
      </geometry>
      <material name="black"/>
    </visual>
    <collision>
      <origin rpy="1.5707963267948966 0 0" xyz="0 0 0"/>
      <geometry>
        <cylinder length="0.1" radius="0.1"/>
      </geometry>
    </collision>
    <inertial>
      <mass value="0.3"/>
      <inertia ixx="0.001" ixy="0.001" ixz="0.001" iyy="0.001" iyz="0.001" izz="0.001"/>
    </inertial>
  </link>
  <joint name="left_front_wheel_base_joint" type="continuous">
    <axis rpy="0 0 0" xyz="0 0 1"/>
    <parent link="base_link"/>
    <child link="left_front_wheel_base"/>
    <origin rpy="0 0 0" xyz="0.5 -0.5 0"/>
  </joint>
  <joint name="left_front_wheel_joint" type="continuous">
    <axis rpy="0 0 0" xyz="0 1 0"/>
    <parent link="left_front_wheel_base"/>
    <child link="left_front_wheel"/>
    <origin rpy="0 0 0" xyz="0 0 -0.15000000000000002"/>
  </joint>
  <!-- <joint name="${prefix}_${suffix}_wheel_joint_revolute" type="revolute">
      <axis rpy="0 0 0" xyz="0 0 1"/>
      <limit effort ="1000.0" lower="-0.55" upper="0.55" velocity="0.5"/>
      <parent link="${prefix}_${suffix}_wheel"/>
      <child link="${prefix}_${suffix}_wheel"/>
      <origin rpy="0 0 0" xyz="${width*reflectx/2} ${width/2*reflecty} -${wheeldiam/2+.05}"/>
    </joint> -->
  <link name="left_back_wheel_base">
    <inertial>
      <mass value="0.001"/>
      <inertia ixx="0.001" ixy="0.001" ixz="0.001" iyy="0.001" iyz="0.001" izz="0.001"/>
    </inertial>
  </link>
  <link name="left_back_wheel">
    <visual>
      <origin rpy="1.5707963267948966 0 0" xyz="0 0 0"/>
      <geometry>
        <cylinder length="0.1" radius="0.1"/>
      </geometry>
      <material name="black"/>
    </visual>
    <collision>
      <origin rpy="1.5707963267948966 0 0" xyz="0 0 0"/>
      <geometry>
        <cylinder length="0.1" radius="0.1"/>
      </geometry>
    </collision>
    <inertial>
      <mass value="0.3"/>
      <inertia ixx="0.001" ixy="0.001" ixz="0.001" iyy="0.001" iyz="0.001" izz="0.001"/>
    </inertial>
  </link>
  <joint name="left_back_wheel_base_joint" type="continuous">
    <axis rpy="0 0 0" xyz="0 0 1"/>
    <parent link="base_link"/>
    <child link="left_back_wheel_base"/>
    <origin rpy="0 0 0" xyz="-0.5 -0.5 0"/>
  </joint>
  <joint name="left_back_wheel_joint" type="continuous">
    <axis rpy="0 0 0" xyz="0 1 0"/>
    <parent link="left_back_wheel_base"/>
    <child link="left_back_wheel"/>
    <origin rpy="0 0 0" xyz="0 0 -0.15000000000000002"/>
  </joint>
  <!-- <joint name="${prefix}_${suffix}_wheel_joint_revolute" type="revolute">
      <axis rpy="0 0 0" xyz="0 0 1"/>
      <limit effort ="1000.0" lower="-0.55" upper="0.55" velocity="0.5"/>
      <parent link="${prefix}_${suffix}_wheel"/>
      <child link="${prefix}_${suffix}_wheel"/>
      <origin rpy="0 0 0" xyz="${width*reflectx/2} ${width/2*reflecty} -${wheeldiam/2+.05}"/>
    </joint> -->
</robot>
